<?xml version="1.0"?>
<robot name="kr1205" xmlns:xacro="http://www.ros.org/wiki/xacro">

  <material name="black">
    <color rgba="0.5 0.5 0.5 1"/>
  </material>

  <!-- Base Link -->
  <link name="base_link">
    <visual>
      <geometry>
        <mesh filename="file:///home/mo/Thesis/src/robot_control/meshes/visual/base_link.stl" scale="0.001 0.001 0.001"/>
      </geometry>
      <material name="black"/>
    </visual>
  </link>

  <!-- joint_1 -->
  <joint name="joint_1" type="revolute">
    <parent link="base_link"/>
    <child link="link_1"/>
    <origin xyz="0.049 0.0 0.197" rpy="0 0 0"/>
    <axis xyz="0 0 1"/>
    <limit lower="-3.14" upper="3.14" effort="100" velocity="1.0"/>
  </joint>
  <link name="link_1">
    <visual>
      <geometry>
        <mesh filename="file:///home/mo/Thesis/src/robot_control/meshes/visual/link_1.stl" scale="0.001 0.001 0.001"/>
      </geometry>
      <material name="black"/>
    </visual>
  </link>

  <!-- joint_2 -->
  <joint name="joint_2" type="revolute">
    <parent link="link_1"/>
    <child link="link_2"/>
    <origin xyz="0.001 -0.0857 0.0007" rpy="0 0 0"/>
    <axis xyz="0 1 0"/>
    <limit lower="-3.14" upper="3.14" effort="100" velocity="1.0"/>
  </joint>
  <link name="link_2">
    <visual>
      <geometry>
        <mesh filename="file:///home/mo/Thesis/src/robot_control/meshes/visual/link_2.stl" scale="0.001 0.001 0.001"/>
      </geometry>
      <material name="black"/>
    </visual>
  </link>

  <!-- joint_3 -->
  <joint name="joint_3" type="revolute">
    <parent link="link_2"/>
    <child link="link_3"/>
    <origin xyz="-0.01111 0.0 0.61625" rpy="0 0 0"/>
    <axis xyz="0 0 1"/>
    <limit lower="-3.14" upper="3.14" effort="100" velocity="1.0"/>
  </joint>
  <link name="link_3">
    <visual>
      <geometry>
        <mesh filename="file:///home/mo/Thesis/src/robot_control/meshes/visual/link_3.stl" scale="0.001 0.001 0.001"/>
      </geometry>
      <material name="black"/>
    </visual>
  </link>

  <!-- joint_4 -->
  <joint name="joint_4" type="revolute">
    <parent link="link_3"/>
    <child link="link_4"/>
    <origin xyz="0.002 0.08405 0.003" rpy="0 0 0"/>
    <axis xyz="0 1 0"/>
    <limit lower="-3.14" upper="3.14" effort="100" velocity="1.0"/>
  </joint>
  <link name="link_4">
    <visual>
      <geometry>
        <mesh filename="file:///home/mo/Thesis/src/robot_control/meshes/visual/link_4.stl" scale="0.001 0.001 0.001"/>
      </geometry>
      <material name="black"/>
    </visual>
  </link>

  <!-- joint_5 -->
  <joint name="joint_5" type="revolute">
    <parent link="link_4"/>
    <child link="link_5"/>
    <origin xyz="-0.0405 0.002 0.574" rpy="0 0 0"/>
    <axis xyz="0.0 0.0 1.0"/>
    <limit lower="-3.14" upper="3.14" effort="100" velocity="1.0"/>
  </joint>
  <link name="link_5">
    <visual>
      <geometry>
        <mesh filename="file:///home/mo/Thesis/src/robot_control/meshes/visual/link_5.stl" scale="0.001 0.001 0.001"/>
      </geometry>
      <material name="black"/>
    </visual>
  </link>

  <!-- joint_6 -->
  <joint name="joint_6" type="revolute">
    <parent link="link_5"/>
    <child link="link_6"/>
    <origin xyz="0.0 0.109 0.003" rpy="0 0 0"/>
    <axis xyz="0 1 0"/>
    <limit lower="-3.14" upper="3.14" effort="100" velocity="1.0"/>
  </joint>
  <link name="link_6">
    <visual>
      <geometry>
        <mesh filename="file:///home/mo/Thesis/src/robot_control/meshes/visual/link_6.stl" scale="0.001 0.001 0.001"/>
      </geometry>
      <material name="black"/>
    </visual>
  </link>

  <!-- joint_7 -->
  <joint name="joint_7" type="revolute">
    <parent link="link_6"/>
    <child link="link_7"/>
    <origin xyz="-0.001 -0.004 -0.002" rpy="0 0 0"/>
    <axis xyz="0 0 1"/>
    <limit lower="-3.14" upper="3.14" effort="100" velocity="1.0"/>
  </joint>
  <link name="link_7">
    <visual>
      <geometry>
        <mesh filename="file:///home/mo/Thesis/src/robot_control/meshes/visual/link_7.stl" scale="0.001 0.001 0.001"/>
      </geometry>
      <material name="black"/>
    </visual>
  </link>
</robot>
