<?xml version="1.0"?>
<robot name="six_axis_robot">
  
  <!-- Base Link -->
  <link name="base_link"/>
  
  <!-- Links and Joints -->
  <joint name="joint1" type="revolute">
    <parent link="base_link"/>
    <child link="link1"/>
    <origin xyz="0 0 0.3" rpy="0 0 0"/>
    <axis xyz="0 0 1"/>
    <limit lower="-3.14" upper="3.14" effort="100" velocity="1.0"/>
  </joint>
  <link name="link1">
    <visual>
      <geometry>
        <cylinder radius="0.9" length="1.5"/> <!-- Dickerer Arm -->
      </geometry>
      <material name="blue">
        <color rgba="0 0 1 1"/>
      </material>
    </visual>
  </link>
  
  <joint name="joint2" type="revolute">
    <parent link="link1"/>
    <child link="link2"/>
    <origin xyz="0 0 0.3" rpy="0 0 0"/>
    <axis xyz="0 1 0"/>
    <limit lower="-3.14" upper="3.14" effort="100" velocity="1.0"/>
  </joint>
  <link name="link2">
    <visual>
      <geometry>
        <cylinder radius="0.12" length="0.4"/> <!-- Dickerer Arm -->
      </geometry>
      <material name="red">
        <color rgba="1 0 0 1"/>
      </material>
    </visual>
  </link>
  
  <joint name="joint3" type="revolute">
    <parent link="link2"/>
    <child link="link3"/>
    <origin xyz="0 0 0.4" rpy="0 0 0"/>
    <axis xyz="0 1 0"/>
    <limit lower="-3.14" upper="3.14" effort="100" velocity="1.0"/>
  </joint>
  <link name="link3">
    <visual>
      <geometry>
        <cylinder radius="0.1" length="0.3"/> <!-- Dickerer Arm -->
      </geometry>
      <material name="green">
        <color rgba="0 1 0 1"/>
      </material>
    </visual>
  </link>
  
  <joint name="joint4" type="revolute">
    <parent link="link3"/>
    <child link="link4"/>
    <origin xyz="0 0 0.3" rpy="0 0 0"/>
    <axis xyz="1 0 0"/>
    <limit lower="-3.14" upper="3.14" effort="100" velocity="1.0"/>
  </joint>
  <link name="link4">
    <visual>
      <geometry>
        <cylinder radius="0.09" length="0.2"/> <!-- Dickerer Arm -->
      </geometry>
      <material name="yellow">
        <color rgba="1 1 0 1"/>
      </material>
    </visual>
  </link>
  
  <joint name="joint5" type="revolute">
    <parent link="link4"/>
    <child link="link5"/>
    <origin xyz="0 0 0.2" rpy="0 0 0"/>
    <axis xyz="0 1 0"/>
    <limit lower="-3.14" upper="3.14" effort="100" velocity="1.0"/>
  </joint>
  <link name="link5">
    <visual>
      <geometry>
        <cylinder radius="0.07" length="0.15"/> <!-- Dickerer Arm -->
      </geometry>
      <material name="red">
        <color rgba="0 1 1 1"/>
      </material>
    </visual>
  </link>
  
  <joint name="joint6" type="revolute">
    <parent link="link5"/>
    <child link="link6"/>
    <origin xyz="0 0 0.15" rpy="0 0 0"/>
    <axis xyz="1 0 0"/>
    <limit lower="-3.14" upper="3.14" effort="100" velocity="1.0"/>
  </joint>
  <link name="link6">
    <visual>
      <geometry>
        <cylinder radius="0.06" length="0.1"/> <!-- Dickerer Arm -->
      </geometry>
      <material name="red">
        <color rgba="1 0 1 1"/>
      </material>
    </visual>
  </link>
  
</robot>



